Workbook

Sheet BS
B3: SaleSmart Co
B4: Statement of Financial Position
B5: As at 31st December
D6: Current year | E6: Previous year
B7: in USD million | C7: Note | D7: Y3 | E7: Y2 | F7: Y1
B9: ASSETS
B10: Non-current assets
B11: Property, plant and equipment | C11: 5 | D11: 107099 | E11: 105050 | F11: 104077
B12: Intangible assets | C12: 7 | D12: 1346 | E12: 1209 | F12: 849
B13: Deferred tax assets | C13: 16 | D13: 691 | E13: 642 | F13: 719
B14: Loans granted | C14: 9 | D14: 1198 | E14: 368 | F14: 318
B15: Total non-current assets | D15: =SUM(D11:D14) -> 110334 | E15: =SUM(E11:E14) -> 107269 | F15: =SUM(F11:F14) -> 105963
B17: Current assets
B18: Inventories | C18: 10 | D18: 25369 | E18: 23758 | F18: 23432
B19: Trade and other receivables | C19: 11 | D19: 26247 | E19: 24617 | F19: 26115
B20: Marketable securities | C20: 9 | D20: 3346 | E20: 3129 | F20: 3045
B21: Cash and cash equivalents | C21: 12 | D21: 15945 | E21: 9497 | F21: 2998
B22: Total current assets | D22: =SUM(D18:D21) -> 70907 | E22: =SUM(E18:E21) -> 61001 | F22: =SUM(F18:F21) -> 55590
B23: Total assets | D23: =D15+D22 -> 181241 | E23: =E15+E22 -> 168270 | F23: =F22+F15 -> 161553
B25: EQUITY AND LIABILITIES
B26: Capital and reserves attributable to owners
B27: Common share capital | C27: 13 | D27: 24867 | E27: 22802 | F27: 20345
B28: Additional paid-in capital | D28: 11802 | E28: 11980 | F28: 13802
B29: Retained earnings | D29: 61141 | E29: 50504 | F29: 40390
B30: Total owners' equity | D30: =SUM(D27:D29) -> 97810 | E30: =SUM(E27:E29) -> 85286 | F30: =SUM(F27:F29) -> 74537
B31: Non-controlling interest | D31: 33628 | E31: 28496 | F31: 24246
B32: Total equity | D32: =D30+D31 -> 131438 | E32: =E30+E31 -> 113782 | F32: =F30+F31 -> 98783
B34: Liabilities
B35: Non-current liabilities
B36: Long-term debt | C36: 14 | D36: 16982 | E36: 20994 | F36: 25781
B37: Deferred tax liabilities | C37: 16 | D37: 797 | E37: 793 | F37: 669
B38: Retirement benefit obligations | C38: 15 | D38: 522 | E38: 421 | F38: 377
B39: Total non-current liabilities | D39: =SUM(D36:D38) -> 18301 | E39: =SUM(E36:E38) -> 22208 | F39: =SUM(F36:F38) -> 26827
B41: Current liabilities
B42: Short-term debt | C42: 14 | D42: 12492 | E42: 14022 | F42: 17970
B43: Trade and other payables | C43: 18 | D43: 18699 | E43: 18096 | F43: 17802
B44: Current income tax liabilities | D44: 311 | E44: 162 | F44: 171
B45: Total current liabilities | D45: =SUM(D42:D44) -> 31502 | E45: =SUM(E42:E44) -> 32280 | F45: =SUM(F42:F44) -> 35943
B46: Total liabilities | D46: =D39+D45 -> 49803 | E46: =E39+E45 -> 54488 | F46: =F39+F45 -> 62770
B47: Total equity and liabilities | D47: =D46+D32 -> 181241 | E47: =E46+E32 -> 168270 | F47: =F46+F32 -> 161553
...

Sheet P&L
B3: SaleSmart Co
B4: Statement of Comprehensive Income
B5: For the Year Ended 31st December
D7: Current year | E7: Previous year
B8: in USD million | C8: Note | D8: Y3 | E8: Y2
B10: Revenue
B11: Sales revenue | C11: 19 | D11: 191504 | E11: 172829
B12: Other revenue from operating activity | C12: 19 | D12: 7341 | E12: 7312
B13: Total Revenue | D13: =SUM(D11:D12) -> 198845 | E13: =SUM(E11:E12) -> 180141
B15: Cost of goods sold (COGS) | D15: -150291.84 | E15: -138615.84
B17: Gross Profit | D17: =D13+D15 -> 48553.16 | E17: =E13+E15 -> 41525.16
B19: Administrative costs | D19: -5348.82 | E19: -4906.32
B20: Selling costs | D20: -17612.34 | E20: -15989.84
B21: Other costs | D21: -3041 | E21: -2032
B22: Total operating expenses | D22: =SUM(D19:D21) -> -26002.16 | E22: =SUM(E19:E21) -> -22928.16
B24: Operating profit (EBIT) | D24: =D17+D22 -> 22551 | E24: =E17+E22 -> 18597
B26: Interest expense | C26: 21 | D26: -2725 | E26: -2992
B28: Profit before tax (EBT) | D28: =D24+D26 -> 19826 | E28: =E24+E26 -> 15605
B30: Income tax expense | C30: 22 | D30: -2128 | E30: -1643
B32: Net income | D32: =D28+D30 -> 17698 | E32: =E28+E30 -> 13962
B34: Profit for the year attributable to:
B35: Equity holders of the Company | D35: 12558 | E35: 10006
B36: Non-controlling interest | D36: 5140 | E36: 3956
D37: =SUM(D35:D36) -> 17698 | E37: =SUM(E35:E36) -> 13962
B38: Other comprehensive income
B39: Items that will not be reclassified to profit or loss
B40: Gains from revaluation of land and buildings | D40: 0 | E40: 1037
B41: Total other comprehensive income for the year | D41: =SUM(D40) -> 0 | E41: =SUM(E40) -> 1037
B43: Total comprehensive income for the year | D43: =D37+D41 -> 17698 | E43: =E37+E41 -> 14999
B45: Total comprehensive income for the year attributable to:
B46: Equity holders of the Company | D46: 12558 | E46: 10749
B47: Non-controlling interest | D47: 5140 | E47: 4250
D48: =SUM(D46:D47) -> 17698 | E48: =SUM(E46:E47) -> 14999
B50: Common shares outstanding | D50: 10000 | E50: 10000
B51: Common dividend per share ($) | D51: 0.88 | E51: 0.65
B52: Total dividends declared | D52: =D50*D51 -> 8800 | E52: =E50*E51 -> 6500
B53: Share price (in $) | D53: 2.95 | E53: 2.15
B54: Market capitalization | D54: =D50*D53 -> 29500 | E54: =E50*E53 -> 21500
B55: * lease payments = | D55: -2281 | E55: -2475

Sheet Activity ratios
B3: Ratio | E3: Current year (Y3) | I3: Previous year (Y2) | M3: Meaning
B5: 1. Receivables turnover = | C5: annual sales | E5: ='P&L'!D13 -> 198845 | F5: = | G5: =E5/E6 -> 7.818693 | I5: ='P&L'!E13 -> 180141 | J5: = | K5: =I5/I6 -> 7.1016715 | M5: The efficiency of a company in collecting its trade receivables
C6: average receivables | E6: =AVERAGE(BS!D19:E19) -> 25432 | I6: =AVERAGE(BS!E19:F19) -> 25366
B9: 2. Days of sales outstanding = | C9: 365 | E9: 365 | F9: = | G9: =E9/E10 -> 46.682994 | I9: 365 | J9: = | K9: =I9/I10 -> 51.396351 | M9: The average number of days a company takes to collect its receivables from clients
C10: receivables turnover | E10: =G5 -> 7.818693 | I10: =K5 -> 7.1016715
B13: 3. Inventory turnover = | C13: cost of goods sold | E13: =-'P&L'!D15 -> 150291.84 | F13: = | G13: =E13/E14 -> 6.1185027 | I13: =-'P&L'!E15 -> 138615.84 | J13: = | K13: =I13/I14 -> 5.8747972 | M13: The efficiency of a company in terms of inventory management
C14: average inventory | E14: =AVERAGE(BS!D18:E18) -> 24563.5 | I14: =AVERAGE(BS!E18:F18) -> 23595
B17: 4. Days of inventory on hand = | C17: 365 | E17: 365 | F17: = | G17: =E17/E18 -> 59.655118 | I17: 365 | J17: = | K17: =I17/I18 -> 62.129804 | M17: The average inventory processing period
C18: inventory turnover | E18: =G13 -> 6.1185027 | I18: =K13 -> 5.8747972
B21: 5. Payables turnover = | C21: purchases | E21: =BS!D18-BS!E18+(-'P&L'!D15) -> 151902.84 | F21: = | G21: =E21/E22 -> 8.256711 | I21: =BS!E18-BS!F18+(-'P&L'!E15) -> 138941.84 | J21: = | K21: =I21/I22 -> 7.7409237 | M21: The efficiency of a company in allowing trade credit to suppliers | N21: * Purchases = ending inventory – beginning inventory + cost of goods sold
C22: average trade payables | E22: =AVERAGE(BS!D43:E43) -> 18397.5 | I22: =AVERAGE(BS!E43:F43) -> 17949
B25: 6. Number of days of payables = | C25: 365 | E25: 365 | F25: = | G25: =E25/E26 -> 44.206464 | I25: 365 | J25: = | K25: =I25/I26 -> 47.151995 | M25: The average number of days a company takes to pay its suppliers
C26: payables turnover | E26: =G21 -> 8.256711 | I26: =K21 -> 7.7409237
B29: 7. Fixed assets turnover = | C29: revenue | E29: ='P&L'!D13 -> 198845 | F29: = | G29: =E29/E30 -> 1.8745787 | I29: ='P&L'!E13 -> 180141 | J29: = | K29: =I29/I30 -> 1.7227905 | M29: The efficiency of a firm in utilizing its fixed assets
C30: average net fixed assets | E30: =AVERAGE(BS!D11:E11) -> 106074.5 | I30: =AVERAGE(BS!E11:F11) -> 104563.5
B33: 8. Working capital turnover = | C33: revenue | E33: ='P&L'!D13 -> 198845 | F33: = | G33: =E33/E34 -> 5.8375657 | I33: ='P&L'!E13 -> 180141 | J33: = | K33: =I33/I34 -> 7.4487678 | M33: The efficiency of a firm in managing its working capital (current assets - current liabilities)
C34: average working capital | E34: =AVERAGE(BS!D22:E22)-AVERAGE(BS!D45:E45) -> 34063 | I34: =AVERAGE(BS!E22:F22)-AVERAGE(BS!E45:F45) -> 24184
B37: 9. Total assets turnover = | C37: revenue | E37: ='P&L'!D13 -> 198845 | F37: = | G37: =E37/E38 -> 1.1378469 | I37: ='P&L'!E13 -> 180141 | J37: = | K37: =I37/I38 -> 1.0923495 | M37: The efficiency of a firm in using its total assets to create revenue
C38: average total assets | E38: =AVERAGE(BS!D23:E23) -> 174755.5 | I38: =AVERAGE(BS!E23:F23) -> 164911.5
B41: 10. Cash conversion cycle = | C41: days of sales outstanding | E41: =G9 -> 46.682994 | F41: = | G41: =E41+E43-E45 -> 62.131648 | I41: =K9 -> 51.396351 | J41: = | K41: =I41+I43-I45 -> 66.374159 | M41: The number of days a company takes to convert its investments in inventory and other resources into cash flows from sales
E42: + | I42: +
C43: plus: days of inventory on hand | E43: =G17 -> 59.655118 | I43: =K17 -> 62.129804
E44: - | I44: -
C45: less: number of days of payables | E45: =G25 -> 44.206464 | I45: =K25 -> 47.151995
B48: 11. Equity turnover = | C48: revenue | E48: ='P&L'!D13 -> 198845 | F48: = | G48: =E48/E49 -> 1.6217682 | I48: ='P&L'!E13 -> 180141 | J48: = | K48: =I48/I49 -> 1.6949263 | M48: The efficiency of a firm in utilizing equity to create revenue
C49: average total equity | E49: =AVERAGE(BS!D32:E32) -> 122610 | I49: =AVERAGE(BS!E32:F32) -> 106282.5

Sheet Liquidity ratios
B3: Ratio | E3: Current year (Y3) | I3: Previous year (Y2) | M3: Meaning
B5: 1. Current ratio = | C5: current assets | E5: =BS!D22 -> 70907 | F5: = | G5: =E5/E6 -> 2.250873 | I5: =BS!E22 -> 61001 | J5: = | K5: =I5/I6 -> 1.889746 | M5: Ability to meet current liabilities (with total current assets)
C6: current liabilities | E6: =BS!D45 -> 31502 | I6: =BS!E45 -> 32280
B9: 2. Quick ratio = | C9: cash + marketable securities + receivables | E9: =SUM(BS!D19:D21) -> 45538 | F9: = | G9: =E9/E10 -> 1.445559 | I9: =SUM(BS!E19:E21) -> 37243 | J9: = | K9: =I9/I10 -> 1.1537485 | M9: Ability to meet current liabilities (with total current assets, excluding inventory)
C10: current liabilities | E10: =BS!D45 -> 31502 | I10: =BS!E45 -> 32280
B13: 3. Cash ratio = | C13: cash + marketable securities | E13: =SUM(BS!D20:D21) -> 19291 | F13: = | G13: =E13/E14 -> 0.61237382 | I13: =SUM(BS!E20:E21) -> 12626 | J13: = | K13: =I13/I14 -> 0.39114002 | M13: Ability to meet current liabilities (with cash and marketable securities only)
C14: current liabilities | E14: =BS!D45 -> 31502 | I14: =BS!E45 -> 32280
B17: 4. Defensive interval = | C17: cash + marketable securities + receivables | E17: =SUM(BS!D19:D21) -> 45538 | F17: = | G17: =E17/E18 -> 94.282108 | I17: =SUM(BS!E19:E21) -> 37243 | J17: = | K17: =I17/I18 -> 84.14856 | M17: The number of days a company can cover its average daily expenses with the use of current liquid assets only
C18: average daily expenditure | E18: =-('P&L'!D15+'P&L'!D19+'P&L'!D20+'P&L'!D21)/365 -> 482.99726 | I18: =-('P&L'!E15+'P&L'!E19+'P&L'!E20+'P&L'!E21)/365 -> 442.5863

Sheet Solvency ratios
B3: Ratio | E3: Current year (Y3) | I3: Previous year (Y2) | M3: Meaning
B5: 1. Debt-to-equity = | C5: total debt | E5: =BS!D42+BS!D36 -> 29474 | F5: = | G5: =E5/E6 -> 0.22424261 | I5: =BS!E42+BS!E36 -> 35016 | J5: = | K5: =I5/I6 -> 0.30774639 | M5: Debt as a percentage of total equity
C6: total shareholder's equity | E6: =BS!D32 -> 131438 | I6: =BS!E32 -> 113782
B9: 2. Debt-to-capital = | C9: total debt | E9: =BS!D36+BS!D42 -> 29474 | F9: = | G9: =E9/E10 -> 0.18316844 | I9: =BS!E36+BS!E42 -> 35016 | J9: = | K9: =I9/I10 -> 0.23532574 | M9: Debt as a percentage of total capital
C10: total debt + total shareholder's equity | E10: =BS!D36+BS!D42+BS!D32 -> 160912 | I10: =BS!E36+BS!E42+BS!E32 -> 148798
B13: 3. Debt-to-assets = | C13: total debt | E13: =BS!D36+BS!D42 -> 29474 | F13: = | G13: =E13/E14 -> 0.16262325 | I13: =BS!E36+BS!E42 -> 35016 | J13: = | K13: =I13/I14 -> 0.20809413 | M13: Debt as a percentage of total assets
C14: total assets | E14: =BS!D23 -> 181241 | I14: =BS!E23 -> 168270
B17: 4. Interest coverage = | C17: earnings before interest and taxes | E17: ='P&L'!D24 -> 22551 | F17: = | G17: =E17/E18 -> 8.2755963 | I17: ='P&L'!E24 -> 18597 | J17: = | K17: =I17/I18 -> 6.2155749 | M17: The ability to cover interest expenses
C18: interest payments | E18: =-'P&L'!D26 -> 2725 | I18: =-'P&L'!E26 -> 2992
B21: 5. Fixed charge coverage = | C21: earnings before interest and taxes + lease payments | E21: ='P&L'!D24-'P&L'!D55 -> 24832 | F21: = | G21: =E21/E22 -> 4.9604475 | I21: ='P&L'!E24-'P&L'!E55 -> 21072 | J21: = | K21: =I21/I22 -> 3.8543991 | M21: The ability to cover interest and lease expenses
C22: interest payments + lease payments | E22: =-'P&L'!D26-'P&L'!D55 -> 5006 | I22: =-'P&L'!E26-'P&L'!E55 -> 5467
B25: 6. Financial leverage = | C25: average total assets | E25: =AVERAGE(BS!D23:E23) -> 174755.5 | F25: = | G25: =E25/E26 -> 1.4252957 | I25: =AVERAGE(BS!E23:F23) -> 164911.5 | J25: = | K25: =I25/I26 -> 1.5516336 | M25: An indicator of a company's debt financing usage
C26: average total equity | E26: =AVERAGE(BS!D32:E32) -> 122610 | I26: =AVERAGE(BS!E32:F32) -> 106282.5

Sheet Profitability ratios
B3: Ratio | E3: Current year (Y3) | I3: Previous year (Y2) | M3: Meaning
B5: 1. Gross profit margin = | C5: gross profit | E5: ='P&L'!D17 -> 48553.16 | F5: = | G5: =E5/E6 -> 0.24417592 | I5: ='P&L'!E17 -> 41525.16 | J5: = | K5: =I5/I6 -> 0.23051476 | M5: Gross profitability as a percentage of total revenue
C6: revenue | E6: ='P&L'!D13 -> 198845 | I6: ='P&L'!E13 -> 180141
B9: 2. Operating profit margin = | C9: operating income (EBIT) | E9: ='P&L'!D24 -> 22551 | F9: = | G9: =E9/E10 -> 0.11340994 | I9: ='P&L'!E24 -> 18597 | J9: = | K9: =I9/I10 -> 0.1032358 | M9: Operating profitability (before interest and tax) as a percentage of total revenue
C10: revenue | E10: ='P&L'!D13 -> 198845 | I10: ='P&L'!E13 -> 180141
B13: 3. Pretax margin = | C13: EBT | E13: ='P&L'!D28 -> 19826 | F13: = | G13: =E13/E14 -> 0.099705801 | I13: ='P&L'!E28 -> 15605 | J13: = | K13: =I13/I14 -> 0.086626587 | M13: Operating profitability (before tax) as a percentage of total revenue
C14: revenue | E14: ='P&L'!D13 -> 198845 | I14: ='P&L'!E13 -> 180141
B17: 4. Net profit margin = | C17: net income | E17: ='P&L'!D32 -> 17698 | F17: = | G17: =E17/E18 -> 0.089003998 | I17: ='P&L'!E32 -> 13962 | J17: = | K17: =I17/I18 -> 0.077505954 | M17: Net profitability as a percentage of total revenue
C18: revenue | E18: ='P&L'!D13 -> 198845 | I18: ='P&L'!E13 -> 180141
B21: 5. Return on assets (ROA) = | C21: net income | E21: ='P&L'!D32 -> 17698 | F21: = | G21: =E21/E22 -> 0.10127292 | I21: ='P&L'!E32 -> 13962 | J21: = | K21: =I21/I22 -> 0.084663592 | M21: Net profitability (excluding interest and taxes) as a percentage of total invested funds
C22: average total assets | E22: =AVERAGE(BS!D23:E23) -> 174755.5 | I22: =AVERAGE(BS!E23:F23) -> 164911.5
B25: 6. Operating return on assets (ROA) = | C25: operating profit (EBIT) | E25: ='P&L'!D24 -> 22551 | F25: = | G25: =E25/E26 -> 0.12904315 | I25: ='P&L'!E24 -> 18597 | J25: = | K25: =I25/I26 -> 0.11276958 | M25: Net profitability (including interest and taxes) as a percentage of total invested funds
C26: average total assets | E26: =E22 -> 174755.5 | I26: =I22 -> 164911.5
B29: 7. Return on total capital = | C29: operating profit (EBIT) | E29: =E25 -> 22551 | F29: = | G29: =E29/E30 -> 0.14562655 | I29: =I25 -> 18597 | J29: = | K29: =I29/I30 -> 0.12766878 | M29: Operating profitability as a percentage of total capital
C30: average total capital | E30: =AVERAGE(BS!D32:E32)+AVERAGE(BS!D36:E36)+AVERAGE(BS!D42:E42) -> 154855 | I30: =AVERAGE(BS!E32:F32)+AVERAGE(BS!E36:F36)+AVERAGE(BS!E42:F42) -> 145666
B33: 8. Return on equity (RoE) | C33: net income | E33: ='P&L'!D32 -> 17698 | F33: = | G33: =E33/E34 -> 0.14434385 | I33: ='P&L'!E32 -> 13962 | J33: = | K33: =I33/I34 -> 0.13136688 | M33: Net profitability as a percentage of total equity
C34: average equity | E34: =AVERAGE(BS!D32:E32) -> 122610 | I34: =AVERAGE(BS!E32:F32) -> 106282.5

Sheet Valuation ratios
B3: Ratio | E3: Current year (Y3) | I3: Previous year (Y2) | M3: Meaning
B5: 1. Earnings per share (EPS) = | C5: Net Income - preferred dividends | E5: ='P&L'!D32 -> 17698 | F5: = | G5: =E5/E6 -> 1.7698 | I5: ='P&L'!E32 -> 13962 | J5: = | K5: =I5/I6 -> 1.3962 | M5: Income earned per 1 common share outstanding
C6: Outstanding number of common shares | E6: ='P&L'!D50 -> 10000 | I6: ='P&L'!E50 -> 10000
B9: 2. Price earnings (P/E) ratio = | C9: Share price | E9: ='P&L'!D53 -> 2.95 | F9: = | G9: =E9/E10 -> 1.666855 | I9: ='P&L'!E53 -> 2.15 | J9: = | K9: =I9/I10 -> 1.539894 | M9: The price that investors are willing to pay per $1 of earnings
C10: Earnings per share (EPS) | E10: =G5 -> 1.7698 | I10: =K5 -> 1.3962
B13: 3. P/E ratio (company wide) = | C13: Market capitalization | E13: ='P&L'!D54 -> 29500 | F13: = | G13: =E13/E14 -> 1.666855 | I13: ='P&L'!E54 -> 21500 | J13: = | K13: =I13/I14 -> 1.539894 | M13: Total price that investors are willing to pay for a company's Net income
C14: Net income | E14: ='P&L'!D32 -> 17698 | I14: ='P&L'!E32 -> 13962
B17: 4. Dividend yield = | C17: Dividend declared (per share) | E17: ='P&L'!D51 -> 0.88 | F17: = | G17: =E17/E18 -> 0.29830508 | I17: ='P&L'!E51 -> 0.65 | J17: = | K17: =I17/I18 -> 0.30232558 | M17: The "portion "of a share price that is distributed as dividends
C18: Current share price | E18: ='P&L'!D53 -> 2.95 | I18: ='P&L'!E53 -> 2.15
B21: 5. Retention rate (RR) = | C21: Net income - dividends declared | E21: ='P&L'!D32-'P&L'!D52 -> 8898 | F21: = | G21: =E21/E22 -> 0.50276867 | I21: ='P&L'!E32-'P&L'!E52 -> 7462 | J21: = | K21: =I21/I22 -> 0.53445065 | M21: The "portion" of Net income that is reinvested in the company
C22: Net income | E22: ='P&L'!D32 -> 17698 | I22: ='P&L'!E32 -> 13962
B25: 6. Dividend payout = | C25: Dividends declared | E25: ='P&L'!D52 -> 8800 | F25: = | G25: =E25/E26 -> 0.49723133 | I25: ='P&L'!E52 -> 6500 | J25: = | K25: =I25/I26 -> 0.46554935 | M25: The "portion" of Net income that is distributed as dividends
C26: Net income | E26: ='P&L'!D32 -> 17698 | I26: ='P&L'!E32 -> 13962
B29: 7. Sustainable growth rate (g) = RR x ROE | G29: =G21*'Profitability ratios'!G33 -> 0.072571568 | K29: =K21*'Profitability ratios'!K33 -> 0.070209113 | M29: Equity growth rate

Sheet Summary of performance
D2: SaleSmart Co
B3: Category | C3: Multiple | D3: Previous year | E3: Current year | F3: Procter & Gamble (P&G) | G3: Industry average
B5: Activity Ratios | C5: Days of sales outstanding | D5: ='Activity ratios'!K9 -> 51.396351 | E5: ='Activity ratios'!G9 -> 46.682994 | F5: 26.7 | G5: 31.2
C6: Days of inventory on hand | D6: ='Activity ratios'!K17 -> 62.129804 | E6: ='Activity ratios'!G17 -> 59.655118 | F6: =365/6.93 -> 52.669553 | G6: 50.3
C7: Number of days of payables | D7: ='Activity ratios'!K25 -> 47.151995 | E7: ='Activity ratios'!G25 -> 44.206464 | F7: 48 | G7: 44.1
C8: Cash conversion cycle | D8: ='Activity ratios'!K41 -> 66.374159 | E8: =E5+E6-E7 -> 62.131648 | F8: =F5+F6-F7 -> 31.369553 | G8: =G5+G6-G7 -> 37.4
C9: Total asset turnover | D9: ='Activity ratios'!K37 -> 1.0923495 | E9: ='Activity ratios'!G37 -> 1.1378469 | F9: 0.59 | G9: 1
B11: Liquidity Ratios | C11: Current ratio | D11: ='Liquidity ratios'!K5 -> 1.889746 | E11: ='Liquidity ratios'!G5 -> 2.250873 | F11: 0.75 | G11: 1.4
C12: Quick ratio | D12: ='Liquidity ratios'!K9 -> 1.1537485 | E12: ='Liquidity ratios'!G9 -> 1.445559 | F12: 0.6 | G12: 1
C13: Cash ratio | D13: ='Liquidity ratios'!K13 -> 0.39114002 | E13: ='Liquidity ratios'!G13 -> 0.61237382 | F13: 0.4 | G13: 0.5
B15: Solvency Ratios | C15: Debt-to-equity | D15: ='Solvency ratios'!K5 -> 0.30774639 | E15: ='Solvency ratios'!G5 -> 0.22424261 | F15: 0.6325 | G15: 0.55
C16: Debt-to-capital | D16: ='Solvency ratios'!K9 -> 0.23532574 | E16: ='Solvency ratios'!G9 -> 0.18316844 | F16: 0.3 | G16: 0.28
C17: Financial leverage | D17: ='Solvency ratios'!K25 -> 1.5516336 | E17: ='Solvency ratios'!G25 -> 1.4252957 | F17: 2.683 | G17: 1.9
B19: Profitability Ratios | C19: Gross profit margin | D19: ='Profitability ratios'!K5 -> 0.23051476 | E19: ='Profitability ratios'!G5 -> 0.24417592 | F19: 0.4977 | G19: 0.295
C20: Operating profit margin | D20: ='Profitability ratios'!K9 -> 0.1032358 | E20: ='Profitability ratios'!G9 -> 0.11340994 | F20: 0.0978 | G20: 0.132
C21: Net profit margin | D21: ='Profitability ratios'!K17 -> 0.077505954 | E21: ='Profitability ratios'!G17 -> 0.089003998 | F21: 0.0654 | G21: 0.098
C22: Return on equity (RoE) | D22: ='Profitability ratios'!K33 -> 0.13136688 | E22: ='Profitability ratios'!G33 -> 0.14434385 | F22: 0.104 | G22: 0.144
B24: Valuation Ratios | C24: EPS | D24: ='Valuation ratios'!K5 -> 1.3962 | E24: ='Valuation ratios'!G5 -> 1.7698 | F24: 1.84 | G24: 1.83
C25: P/E ratio | D25: ='Valuation ratios'!K9 -> 1.539894 | E25: ='Valuation ratios'!G9 -> 1.666855 | F25: 62.15 | G25: 25.5
C26: Share price | D26: =D24*D25 -> 2.15 | E26: =E24*E25 -> 2.95 | F26: =F24*F25 -> 114.356 | G26: =G24*G25 -> 46.665

Sheet Forecast
B2: Base-case scenario | D2: Previous previous year | E2: Previous year | F2: Current year
B3: in USD million | D3: Y1 | E3: Y2 | F3: Y3 | G3: Y4 | H3: Y5 | I3: Y6 | J3: Y7 | K3: Y8
M4: Gross profit margin (GPM) = | N4: gross profit
B5: Revenue | D5: 163196.36 | E5: ='P&L'!E13 -> 180141 | F5: ='P&L'!D13 -> 198845 | G5: =-G7/(1-G11) -> 216549.98 | H5: =-H7/(1-H11) -> 235850.38 | I5: =-I7/(1-I11) -> 256892.11 | J5: =-J7/(1-J11) -> 279834.68 | K5: =-K7/(1-K11) -> 304852.46 | N5: revenue
B6: Growth % | E6: =E5/D5-1 -> 0.10382978 | F6: =F5/E5-1 -> 0.10382978
B7: COGS | D7: -127846.93 | E7: ='P&L'!E15 -> -138615.84 | F7: ='P&L'!D15 -> -150291.84 | G7: =F7*(1+G8) -> -162951.34 | H7: =G7*(1+H8) -> -176677.19 | I7: =H7*(1+I8) -> -191559.2 | J7: =I7*(1+J8) -> -207694.77 | K7: =J7*(1+K8) -> -225189.48 | M7: Gross profit margin (GPM) = | N7: revenue - COGS | P7: Gross profit margin (GPM) | Q7: = | R7: 1 - | S7: COGS
B8: Growth % | E8: =E7/D7-1 -> 0.084232798 | F8: =F7/E7-1 -> 0.084232798 | G8: =F8 -> 0.084232798 | H8: =G8 -> 0.084232798 | I8: =H8 -> 0.084232798 | J8: =I8 -> 0.084232798 | K8: =J8 -> 0.084232798 | N8: revenue | S8: revenue
B9: Gross Profit | D9: =D5+D7 -> 35349.423 | E9: =E5+E7 -> 41525.16 | F9: =F5+F7 -> 48553.16 | G9: =G5+G7 -> 53598.642 | H9: =H5+H7 -> 59173.195 | I9: =I5+I7 -> 65332.911 | J9: =J5+J7 -> 72139.905 | K9: =K5+K7 -> 79662.98
B10: Growth % | E10: =E9/D9-1 -> 0.17470544 | F10: =F9/E9-1 -> 0.16924679 | G10: =G9/F9-1 -> 0.10391665 | H10: =H9/G9-1 -> 0.1040055 | I10: =I9/H9-1 -> 0.10409638 | J10: =J9/I9-1 -> 0.10418937 | K10: =K9/J9-1 -> 0.10428451 | P10: Revenue | Q10: = | R10: COGS
B11: Gross profit margin | D11: =D9/D5 -> 0.21660669 | E11: =E9/E5 -> 0.23051476 | F11: =F9/F5 -> 0.24417592 | G11: =F11*(1+G12) -> 0.24751164 | H11: =G11*(1+H12) -> 0.25089293 | I11: =H11*(1+I12) -> 0.25432042 | J11: =I11*(1+J12) -> 0.25779473 | K11: =J11*(1+K12) -> 0.2613165 | R11: 1 - GPМ%
B12: % change | E12: =E11-D11 -> 0.013908071 | F12: =F11-E11 -> 0.013661152 | G12: =F12 -> 0.013661152 | H12: =G12 -> 0.013661152 | I12: =H12 -> 0.013661152 | J12: =I12 -> 0.013661152 | K12: =J12 -> 0.013661152
B15: Worst-case scenario | D15: Previous previous year | E15: Previous year | F15: Current year
B16: in USD million | D16: Y1 | E16: Y2 | F16: Y3 | G16: Y4 | H16: Y5 | I16: Y6 | J16: Y7 | K16: Y8
B18: Revenue | D18: =D5 -> 163196.36 | E18: =E5 -> 180141 | F18: =F5 -> 198845 | G18: =-G20/(1-G24) -> 215594.27 | H18: =-H20/(1-H24) -> 233754.38 | I18: =-I20/(1-I24) -> 253444.16 | J18: =-J20/(1-J24) -> 274792.48 | K18: =-K20/(1-K24) -> 297939.01
B19: Growth % | E19: =E6 -> 0.10382978 | F19: =F6 -> 0.10382978
B20: COGS | D20: =D7 -> -127846.93 | E20: =E7 -> -138615.84 | F20: =F7 -> -150291.84 | G20: =F20*(1+G21) -> -162951.34 | H20: =G20*(1+H21) -> -176677.19 | I20: =H20*(1+I21) -> -191559.2 | J20: =I20*(1+J21) -> -207694.77 | K20: =J20*(1+K21) -> -225189.48
B21: Growth % | E21: =E8 -> 0.084232798 | F21: =F8 -> 0.084232798 | G21: =F21 -> 0.084232798 | H21: =G21 -> 0.084232798 | I21: =H21 -> 0.084232798 | J21: =I21 -> 0.084232798 | K21: =J21 -> 0.084232798
B22: Gross Profit | D22: =D9 -> 35349.423 | E22: =E9 -> 41525.16 | F22: =F9 -> 48553.16 | G22: =G18+G20 -> 52642.929 | H22: =H18+H20 -> 57077.19 | I22: =I18+I20 -> 61884.961 | J22: =J18+J20 -> 67097.704 | K22: =K18+K20 -> 72749.532
B23: Growth % | E23: =E10 -> 0.17470544 | F23: =F10 -> 0.16924679
B24: Gross profit margin | D24: =D11 -> 0.21660669 | E24: =E11 -> 0.23051476 | F24: =F11 -> 0.24417592 | G24: =F24*(1+G25) -> 0.24417592 | H24: =G24*(1+H25) -> 0.24417592 | I24: =H24*(1+I25) -> 0.24417592 | J24: =I24*(1+J25) -> 0.24417592 | K24: =J24*(1+K25) -> 0.24417592
B25: % change | E25: =E12 -> 0.013908071 | F25: =F12 -> 0.013661152 | G25: 0 | H25: =G25 -> 0 | I25: =H25 -> 0 | J25: =I25 -> 0 | K25: =J25 -> 0
B28: Best-case scenario | D28: Previous previous year | E28: Previous year | F28: Current year
B29: in USD million | D29: Y1 | E29: Y2 | F29: Y3 | G29: Y4 | H29: Y5 | I29: Y6 | J29: Y7 | K29: Y8
B31: Revenue | D31: =D18 -> 163196.36 | E31: =E18 -> 180141 | F31: =F18 -> 198845 | G31: =-G33/(1-G37) -> 219133.93 | H31: =-H33/(1-H37) -> 241759.91 | I31: =-I33/(1-I37) -> 267042.56 | J31: =-J33/(1-J37) -> 295355.5 | K31: =-K33/(1-K37) -> 327137.8
B32: Growth % | E32: =E19 -> 0.10382978 | F32: =F19 -> 0.10382978
B33: COGS | D33: =D20 -> -127846.93 | E33: =E20 -> -138615.84 | F33: =F20 -> -150291.84 | G33: =F33*(1+G34) -> -162951.34 | H33: =G33*(1+H34) -> -176677.19 | I33: =H33*(1+I34) -> -191559.2 | J33: =I33*(1+J34) -> -207694.77 | K33: =J33*(1+K34) -> -225189.48
B34: Growth % | E34: =E21 -> 0.084232798 | F34: =F21 -> 0.084232798 | G34: =F34 -> 0.084232798 | H34: =G34 -> 0.084232798 | I34: =H34 -> 0.084232798 | J34: =I34 -> 0.084232798 | K34: =J34 -> 0.084232798
B35: Gross Profit | D35: =D22 -> 35349.423 | E35: =E22 -> 41525.16 | F35: =F22 -> 48553.16 | G35: =G31+G33 -> 56182.59 | H35: =H31+H33 -> 65082.723 | I35: =I31+I33 -> 75483.357 | J35: =J31+J33 -> 87660.731 | K35: =K31+K33 -> 101948.31
B36: Growth % | E36: =E23 -> 0.17470544 | F36: =F23 -> 0.16924679
B37: Gross profit margin | D37: =D24 -> 0.21660669 | E37: =E24 -> 0.23051476 | F37: =F24 -> 0.24417592 | G37: =F37*(1+G38) -> 0.25638471 | H37: =G37*(1+H38) -> 0.26920395 | I37: =H37*(1+I38) -> 0.28266414 | J37: =I37*(1+J38) -> 0.29679735 | K37: =J37*(1+K38) -> 0.31163722
B38: % change | E38: =E25 -> 0.013908071 | F38: =F25 -> 0.013661152 | G38: 0.05 | H38: =G38 -> 0.05 | I38: =H38 -> 0.05 | J38: =I38 -> 0.05 | K38: =J38 -> 0.05

Sheet DuPont Analysis
B3: 2-Way DuPont Analysis | C3: RoE | D3: = | E3: net profit margin | F3: x | G3: equity turnover
C5: net income | D5: = | E5: net income | F5: x | G5: revenue
C6: average equity | E6: revenue | G6: average equity
B8: Current year (Y3): | C8: =E8*G8 -> 0.14434385 | D8: = | E8: ='Profitability ratios'!G17 -> 0.089003998 | F8: x | G8: ='Activity ratios'!G48 -> 1.6217682
B9: Previous year (Y2): | C9: =E9*G9 -> 0.13136688 | D9: = | E9: ='Profitability ratios'!K17 -> 0.077505954 | F9: x | G9: ='Activity ratios'!K48 -> 1.6949263
B12: 3-Way DuPont Analysis | C12: RoE | D12: = | E12: net profit margin | F12: x | G12: asset turnover | H12: x | I12: financial leverage ratio
C14: net income | D14: = | E14: net income | F14: x | G14: revenue | H14: x | I14: average total assets
C15: average equity | E15: revenue | G15: average total assets | I15: average equity
B17: Current year (Y3): | C17: =E17*G17*I17 -> 0.14434385 | D17: = | E17: =E8 -> 0.089003998 | F17: x | G17: ='Activity ratios'!G37 -> 1.1378469 | H17: x | I17: ='Solvency ratios'!G25 -> 1.4252957
B18: Previous year (Y2): | C18: =E18*G18*I18 -> 0.13136688 | D18: = | E18: =E9 -> 0.077505954 | F18: x | G18: ='Activity ratios'!K37 -> 1.0923495 | H18: x | I18: ='Solvency ratios'!K25 -> 1.5516336
B21: 5-Way DuPont Analysis | C21: RoE | D21: = | E21: tax burden | F21: x | G21: interest burden | H21: x | I21: operating profit margin | J21: x | K21: asset turnover | L21: x | M21: financial leverage ratio
C23: net income | D23: = | E23: net income | F23: x | G23: EBT | H23: x | I23: EBIT | J23: x | K23: revenue | L23: x | M23: average total assets
C24: average equity | E24: EBT | G24: EBIT | I24: revenue | K24: average total assets | M24: average equity
B26: Current year (Y3): | C26: =E26*G26*I26*K26*M26 -> 0.14434385 | D26: = | E26: ='P&L'!D32/'P&L'!D28 -> 0.8926662 | F26: x | G26: ='P&L'!D28/'P&L'!D24 -> 0.87916279 | H26: x | I26: ='Profitability ratios'!G9 -> 0.11340994 | J26: x | K26: =G17 -> 1.1378469 | L26: x | M26: =I17 -> 1.4252957
B27: Previous year (Y2): | C27: =E27*G27*I27*K27*M27 -> 0.13136688 | D27: = | E27: ='P&L'!E32/'P&L'!E28 -> 0.89471323 | F27: x | G27: ='P&L'!E28/'P&L'!E24 -> 0.83911384 | H27: x | I27: ='Profitability ratios'!K9 -> 0.1032358 | J27: x | K27: =G18 -> 1.0923495 | L27: x | M27: =I18 -> 1.5516336

Sheet Altman's credit score 
D3: Current year | F3: Previous year
B4: Formula | C4: Weight | D4: Ratio | E4: Result | F4: Ratio | G4: Result | H4: Category
B5: 1.2 × (Current assets – Current liabilities)/Total assets + | C5: 1.2 | D5: =(BS!D22-BS!D45)/BS!D23 -> 0.21741769 | E5: =C5*D5 -> 0.26090123 | F5: =(BS!E22-BS!E45)/BS!E23 -> 0.17068402 | G5: =C5*F5 -> 0.20482082 | H5: Liquidity
B6: 1.4 × (Retained earnings/Total assets) + | C6: 1.4 | D6: =BS!D29/BS!D23 -> 0.33734641 | E6: =C6*D6 -> 0.47228497 | F6: =BS!E29/BS!E23 -> 0.30013669 | G6: =C6*F6 -> 0.42019136 | H6: Solvency
B7: 3.3 × (EBIT/Total assets) + | C7: 3.3 | D7: ='P&L'!D24/BS!D23 -> 0.12442549 | E7: =C7*D7 -> 0.41060411 | F7: ='P&L'!E24/BS!E23 -> 0.11051881 | G7: =C7*F7 -> 0.36471207 | H7: Profitability
B8: 1.0 × (Sales/Total assets) | C8: 1 | D8: ='P&L'!D13/BS!D23 -> 1.0971303 | E8: =C8*D8 -> 1.0971303 | F8: ='P&L'!E13/BS!E23 -> 1.0705473 | G8: =C8*F8 -> 1.0705473 | H8: Activity
B9: 0.6 × (Market value of stock/Book value of liabilities) + | C9: 0.6 | D9: ='P&L'!D54/BS!D46 -> 0.5923338 | E9: =C9*D9 -> 0.35540028 | F9: ='P&L'!E54/BS!E46 -> 0.39458229 | G9: =C9*F9 -> 0.23674938 | H9: Valuation
B10: Total Z-score | E10: =SUM(E5:E9) -> 2.5963209 | G10: =SUM(G5:G9) -> 2.297021

Sheet Segment reporting
C3: Current year | F3: Previous year
C4: Revenue | D4: Gross profit | E4: Gross profit margin | F4: Revenue | G4: Gross profit | H4: Gross profit margin | I4: GPM Change
B5: Personal care | C5: 42980 | D5: 7134 | E5: =D5/C5 -> 0.16598418 | F5: 32980 | G5: 5401 | H5: =G5/F5 -> 0.16376592 | I5: =E5-H5 -> 0.0022182599
B6: Home care | C6: 33600 | D6: 6800 | E6: =D6/C6 -> 0.20238095 | F6: 30600 | G6: 5460 | H6: =G6/F6 -> 0.17843137 | I6: =E6-H6 -> 0.02394958
B7: Pharmaceuticals | C7: 15233 | D7: 3679 | E7: =D7/C7 -> 0.24151513 | F7: 14273 | G7: 3370 | H7: =G7/F7 -> 0.23611014 | I7: =E7-H7 -> 0.0054049936
B8: Leisure and entertainment | C8: 20190 | D8: 8350 | E8: =D8/C8 -> 0.41357107 | F8: 19020 | G8: 7344 | H8: =G8/F8 -> 0.38611987 | I8: =E8-H8 -> 0.027451201
B9: Baby & Kids | C9: 86842 | D9: 22590 | E9: =D9/C9 -> 0.26012759 | F9: 83268 | G9: 19950 | H9: =G9/F9 -> 0.23958784 | I9: =E9-H9 -> 0.020539751
B10: Total | C10: ='P&L'!D13 -> 198845 | D10: ='P&L'!D17 -> 48553.16 | E10: =D10/C10 -> 0.24417592 | F10: ='P&L'!E13 -> 180141 | G10: ='P&L'!E17 -> 41525.16 | H10: =G10/F10 -> 0.23051476 | I10: =E10-H10 -> 0.013661152
C13: Current year | F13: Previous year
C14: Revenue | D14: Gross profit | E14: Gross profit margin | F14: Revenue | G14: Gross profit | H14: Gross profit margin
B15: Americas | C15: 127855 | D15: 27134 | E15: =D15/C15 -> 0.21222479 | F15: 113268 | G15: 20401 | H15: =G15/F15 -> 0.18011265
B16: EMEA | C16: 44600 | D16: 10822 | E16: =D16/C16 -> 0.24264574 | F16: 40600 | G16: 9760 | H16: =G16/F16 -> 0.24039409
B17: Asian Pacific | C17: 26390 | D17: 10597 | E17: =D17/C17 -> 0.40155362 | F17: 26273 | G17: 11364 | H17: =G17/F17 -> 0.4325353
B18: Total | C18: =C10 -> 198845 | D18: =D10 -> 48553.16 | E18: =E10 -> 0.24417592 | F18: =F10 -> 180141 | G18: =G10 -> 41525.16 | H18: =H10 -> 0.23051476
